Workbook

Sheet Sheet1
A1: Chem Name | B1: Cas Decimal | C1: RBA Determination | D1: Browne et al. | E1: Judson et al | F1: CERAPP_agonist | G1: CERAPP_antagonist | H1: EDKB_Classification | I1: UPDATED_CLASSIFICATION | L1: Changed from original database | M1: New From Brahnam | N1: new from Judson et al. 2015 | O1: New from Blair et al 2000
A2: Ethynylestradiol | B2: 57-63-6 | C2: strong | D2: strong | E2: 1 | F2: Strong | G2: Strong | H2: active strong | I2: strong
A3: Hexestrol | B3: 84-16-2 | C3: strong | D3: strong | E3: 0.993 | F3: Weak | G3: Strong | H3: active strong | I3: strong
A4: Diethylstilbestrol (DES) | B4: 56-53-1 | C4: strong | E4: 0.943 | F4: Weak | G4: Strong | H4: active strong | I4: strong
A5: Dienestrol | B5: 84-17-3 | C5: strong | F5: Strong | G5: Strong | H5: active strong | I5: strong
A6: Estrone | B6: 53-16-7 | C6: strong | D6: moderate | E6: 0.807 | F6: Strong | G6: Strong | H6: active strong | I6: strong
A7: Mestranol | B7: 72-33-3 | C7: strong | E7: 0.742 | F7: Moderate | G7: Strong | H7: active strong | I7: strong
A8: 17a-Estradiol | B8: 57-91-0 | C8: strong | D8: moderate | E8: 1.06 | F8: Strong | G8: Strong | H8: active strong | I8: strong
A9: Estriol | B9: 50-27-1 | C9: strong | E9: 0.786 | F9: Strong | G9: Strong | H9: active strong | I9: strong
A10: 17b-Estradiol (E2) | B10: 50-28-2 | C10: strong | D10: strong | E10: 0.935 | F10: Strong | G10: Strong | H10: active strong | I10: strong
A11: Moxestrol | B11: 34816-55-2 | C11: strong | F11: Strong | G11: Strong | H11: active strong | I11: strong
A12: Equilin | B12: 474-86-2 | E12: 0.82 | F12: Strong | G12: Strong | H12: #N/A | I12: strong
A13: 4-OH-Estradiol | B13: 5976-61-4 | C13: strong | F13: Strong | G13: Strong | H13: active strong | I13: strong
A14: 17-Deoxyestradiol | B14: 53-63-4 | C14: strong | F14: Strong | G14: Strong | H14: active strong | I14: strong
A15: 2-OH-Estradiol | B15: 362-05-0 | C15: strong | F15: Strong | G15: Strong | H15: active strong | I15: strong
A16: Ethyl 4-hydroxybenzoate | B16: 120-47-8 | C16: weak | D16: veryweak | E16: 0.0864 | F16: VeryWeak | G16: Weak | H16: active weak | I16: weak
A17: p,p'-DDE | B17: 72-55-9 | C17: weak | D17: veryweak | E17: 0.0677 | F17: VeryWeak | G17: VeryWeak | H17: inactive | I17: inactive
A18: p,p'-Methoxychlor | B18: 72-43-5 | C18: weak | D18: veryweak | E18: 0.254 | F18: VeryWeak | G18: Weak | H18: inactive | I18: inactive
A19: o,p'-DDD | B19: 53-19-0 | C19: weak | E19: 0.236 | F19: VeryWeak | G19: Weak | H19: inactive | I19: inactive
A20: 4-Chloro-3-methylphenol | B20: 59-50-7 | C20: weak | E20: 0.0285 | F20: VeryWeak | G20: Weak | H20: active weak | I20: weak
A21: Bis(2-hydroxyphenyl)methane | B21: 207-13-4 | C21: weak | E21: 0.0303 | F21: Weak | G21: Weak | H21: active weak | I21: weak
A22: 4-Chloro-2-methyl phenol | B22: 1570-64-5 | C22: weak | E22: 0.0109 | F22: Suspicious | G22: VeryWeak | H22: active weak | I22: weak
A23: p,p'-DDD | B23: 72-54-8 | C23: weak | E23: 0.0728 | F23: VeryWeak | G23: Suspicious | H23: inactive | I23: inactive
A24: Isoeugenol | B24: 97-54-1 | C24: weak | E24: 0.0124 | F24: Weak | G24: Weak | H24: inactive | I24: inactive
A25: Butylbenzylphthalate | B25: 85-68-7 | C25: weak | D25: veryweak | E25: 0.179 | F25: Suspicious | G25: VeryWeak | H25: inactive | I25: inactive
A26: 2-Hydroxy biphenyl | B26: 90-43-7 | C26: weak | E26: 0.00543 | F26: Weak | G26: VeryWeak | H26: inactive | I26: inactive
A27: Methyl 4-hydroxybenzoate | B27: 99-76-3 | C27: weak | E27: 0.00684 | F27: VeryWeak | G27: Suspicious | H27: active weak | I27: weak
A28: 4-Hydroxybiphenyl | B28: 92-69-3 | C28: weak | E28: 0.219 | F28: VeryWeak | G28: Weak | H28: active weak | I28: weak
A29: cinnamic acid | B29: 140-10-3 | C29: weak | E29: 0.101 | F29: Suspicious | G29: VeryWeak | H29: inactive | I29: inactive
A30: 2-OH-4-Methoxy-benzophenone | B30: 131-57-7 | C30: weak | E30: 0.0645 | F30: VeryWeak | G30: Weak | H30: inactive | I30: inactive
A31: Endosulfan | B31: 115-29-7 | C31: weak | E31: 0.0295 | F31: Suspicious | G31: VeryWeak | H31: inactive | I31: inactive
A32: Triphenyl phosphate | B32: 115-86-6 | C32: weak | E32: 0.0641 | F32: Suspicious | G32: VeryWeak | H32: inactive | I32: inactive
A33: 4-Ethylphenol | B33: 123-07-9 | C33: weak | E33: 0.00352 | F33: Suspicious | G33: VeryWeak | H33: active weak | I33: weak
A34: di-i-Butyl phthalate (DIBP) | B34: 84-69-5 | C34: weak | E34: 0.0283 | F34: Suspicious | G34: VeryWeak | H34: inactive | I34: inactive
A35: Epitestesterone | B35: 481-30-1 | C35: weak | F35: VeryWeak | G35: Moderate | H35: inactive | I35: inactive
A36: di-n-Butyl phthalate (DBuP) | B36: 84-74-2 | C36: weak | D36: veryweak | E36: 0.0265 | F36: Inactive | G36: Inactive | H36: inactive | I36: inactive
A37: 17b-Hydroxyetiocholan-3-one | B37: 571-22-2 | C37: weak | F37: Weak | G37: Strong | H37: inactive | I37: inactive
A38: Chrysene | B38: 218-01-9 | C38: weak | F38: Weak | G38: Moderate | H38: inactive | I38: inactive
A39: "2,4-Hydroxybenzophenone" | B39: 131-56-6 | C39: weak | E39: 0.266 | F39: Weak | G39: Moderate | H39: active weak | I39: weak
A40: Phenol red | B40: 143-74-8 | C40: weak | E40: 0.0409 | F40: Weak | G40: Moderate | H40: active weak | I40: weak
...

Sheet Sheet4

Sheet Sheet2
A1: "cas-140-10-3_min": "alpha-zearalanol", | B1: =_xlfn.TEXTBEFORE(_xlfn.TEXTAFTER(A1,"cas-"),"_") -> 140-10-3 | C1: =INDEX(Sheet1!$A$1:$G$34, MATCH(Sheet2!B1,Sheet1!B:B,0), 1) -> cinnamic acid | D1: =INDEX(Sheet1!$A$1:$G$34, MATCH(Sheet2!B1,Sheet1!B:B,0), 3) -> weak
A2: "cas-34816-55-2_min": "Butyl paraben", | B2: =_xlfn.TEXTBEFORE(_xlfn.TEXTAFTER(A2,"cas-"),"_") -> 34816-55-2 | C2: =INDEX(Sheet1!$A$1:$G$34, MATCH(Sheet2!B2,Sheet1!B:B,0), 1) -> Moxestrol | D2: =INDEX(Sheet1!$A$1:$G$34, MATCH(Sheet2!B2,Sheet1!B:B,0), 3) -> strong
A3: "cas-99-76-3_min": "4-tert-octylphenol", | B3: =_xlfn.TEXTBEFORE(_xlfn.TEXTAFTER(A3,"cas-"),"_") -> 99-76-3 | C3: =INDEX(Sheet1!$A$1:$G$34, MATCH(Sheet2!B3,Sheet1!B:B,0), 1) -> Methyl 4-hydroxybenzoate | D3: =INDEX(Sheet1!$A$1:$G$34, MATCH(Sheet2!B3,Sheet1!B:B,0), 3) -> weak
A4: "cas-474-86-2_min": "Benzophenone-2", | B4: =_xlfn.TEXTBEFORE(_xlfn.TEXTAFTER(A4,"cas-"),"_") -> 474-86-2 | C4: =INDEX(Sheet1!$A$1:$G$34, MATCH(Sheet2!B4,Sheet1!B:B,0), 1) -> Equilin | D4: strong
A5: "cas-115-29-7_min": "Bisphenol A (BPA)", | B5: =_xlfn.TEXTBEFORE(_xlfn.TEXTAFTER(A5,"cas-"),"_") -> 115-29-7 | C5: Endosulfan | D5: =INDEX(Sheet1!$A$1:$G$34, MATCH(Sheet2!B5,Sheet1!B:B,0), 3) -> weak
A6: "cas-72-55-9_min": "alpha-zearalenol", | B6: =_xlfn.TEXTBEFORE(_xlfn.TEXTAFTER(A6,"cas-"),"_") -> 72-55-9 | C6: =INDEX(Sheet1!$A$1:$G$34, MATCH(Sheet2!B6,Sheet1!B:B,0), 1) -> p,p'-DDE | D6: =INDEX(Sheet1!$A$1:$G$34, MATCH(Sheet2!B6,Sheet1!B:B,0), 3) -> weak
A7: "cas-84-17-3_min": "Caffeine", | B7: =_xlfn.TEXTBEFORE(_xlfn.TEXTAFTER(A7,"cas-"),"_") -> 84-17-3 | C7: =INDEX(Sheet1!$A$1:$G$34, MATCH(Sheet2!B7,Sheet1!B:B,0), 1) -> Dienestrol | D7: =INDEX(Sheet1!$A$1:$G$34, MATCH(Sheet2!B7,Sheet1!B:B,0), 3) -> strong
A8: "cas-120-47-8_min": "Diethylstilbestrol (DES)", | B8: =_xlfn.TEXTBEFORE(_xlfn.TEXTAFTER(A8,"cas-"),"_") -> 120-47-8 | C8: =INDEX(Sheet1!$A$1:$G$34, MATCH(Sheet2!B8,Sheet1!B:B,0), 1) -> Ethyl 4-hydroxybenzoate | D8: =INDEX(Sheet1!$A$1:$G$34, MATCH(Sheet2!B8,Sheet1!B:B,0), 3) -> weak
A9: "cas-92-69-3_min": "EE2", | B9: =_xlfn.TEXTBEFORE(_xlfn.TEXTAFTER(A9,"cas-"),"_") -> 92-69-3 | C9: =INDEX(Sheet1!$A$1:$G$34, MATCH(Sheet2!B9,Sheet1!B:B,0), 1) -> 4-Hydroxybiphenyl | D9: =INDEX(Sheet1!$A$1:$G$34, MATCH(Sheet2!B9,Sheet1!B:B,0), 3) -> weak
A10: "cas-50-27-1_min": "17β-estradiol (E2)", | B10: =_xlfn.TEXTBEFORE(_xlfn.TEXTAFTER(A10,"cas-"),"_") -> 50-27-1 | C10: =INDEX(Sheet1!$A$1:$G$34, MATCH(Sheet2!B10,Sheet1!B:B,0), 1) -> Estriol | D10: =INDEX(Sheet1!$A$1:$G$34, MATCH(Sheet2!B10,Sheet1!B:B,0), 3) -> strong
A11: "cas-72-43-5_min": "Melatonin", | B11: =_xlfn.TEXTBEFORE(_xlfn.TEXTAFTER(A11,"cas-"),"_") -> 72-43-5 | C11: =INDEX(Sheet1!$A$1:$G$34, MATCH(Sheet2!B11,Sheet1!B:B,0), 1) -> p,p'-Methoxychlor | D11: =INDEX(Sheet1!$A$1:$G$34, MATCH(Sheet2!B11,Sheet1!B:B,0), 3) -> weak
A12: "cas-1570-64-5_min": "Testosterone", | B12: =_xlfn.TEXTBEFORE(_xlfn.TEXTAFTER(A12,"cas-"),"_") -> 1570-64-5 | C12: =INDEX(Sheet1!$A$1:$G$34, MATCH(Sheet2!B12,Sheet1!B:B,0), 1) -> 4-Chloro-2-methyl phenol | D12: =INDEX(Sheet1!$A$1:$G$34, MATCH(Sheet2!B12,Sheet1!B:B,0), 3) -> weak
A13: "cas-123-07-9_min": "Testosterone", | B13: =_xlfn.TEXTBEFORE(_xlfn.TEXTAFTER(A13,"cas-"),"_") -> 123-07-9 | C13: =INDEX(Sheet1!$A$1:$G$34, MATCH(Sheet2!B13,Sheet1!B:B,0), 1) -> 4-Ethylphenol | D13: =INDEX(Sheet1!$A$1:$G$34, MATCH(Sheet2!B13,Sheet1!B:B,0), 3) -> weak
A14: "cas-90-43-7_min": "Testosterone", | B14: =_xlfn.TEXTBEFORE(_xlfn.TEXTAFTER(A14,"cas-"),"_") -> 90-43-7 | C14: =INDEX(Sheet1!$A$1:$G$34, MATCH(Sheet2!B14,Sheet1!B:B,0), 1) -> 2-Hydroxy biphenyl | D14: =INDEX(Sheet1!$A$1:$G$34, MATCH(Sheet2!B14,Sheet1!B:B,0), 3) -> weak
A15: "cas-57-91-0_min": "Testosterone", | B15: =_xlfn.TEXTBEFORE(_xlfn.TEXTAFTER(A15,"cas-"),"_") -> 57-91-0 | C15: =INDEX(Sheet1!$A$1:$G$34, MATCH(Sheet2!B15,Sheet1!B:B,0), 1) -> 17a-Estradiol | D15: =INDEX(Sheet1!$A$1:$G$34, MATCH(Sheet2!B15,Sheet1!B:B,0), 3) -> strong
A16: "cas-59-50-7_min": "Testosterone", | B16: =_xlfn.TEXTBEFORE(_xlfn.TEXTAFTER(A16,"cas-"),"_") -> 59-50-7 | C16: =INDEX(Sheet1!$A$1:$G$34, MATCH(Sheet2!B16,Sheet1!B:B,0), 1) -> 4-Chloro-3-methylphenol | D16: =INDEX(Sheet1!$A$1:$G$34, MATCH(Sheet2!B16,Sheet1!B:B,0), 3) -> weak
A17: "cas-53-19-0_min": "Testosterone", | B17: =_xlfn.TEXTBEFORE(_xlfn.TEXTAFTER(A17,"cas-"),"_") -> 53-19-0 | C17: =INDEX(Sheet1!$A$1:$G$34, MATCH(Sheet2!B17,Sheet1!B:B,0), 1) -> o,p'-DDD | D17: =INDEX(Sheet1!$A$1:$G$34, MATCH(Sheet2!B17,Sheet1!B:B,0), 3) -> weak
... A33: "cas-5976-61-4_min": "Testosterone", | B33: =_xlfn.TEXTBEFORE(_xlfn.TEXTAFTER(A33,"cas-"),"_") -> 5976-61-4 | C33: =INDEX(Sheet1!$A$1:$G$34, MATCH(Sheet2!B33,Sheet1!B:B,0), 1) -> 4-OH-Estradiol | D33: =INDEX(Sheet1!$A$1:$G$34, MATCH(Sheet2!B33,Sheet1!B:B,0), 3) -> strong

Sheet Sheet3
A1: Epitestesterone | B1: 481-30-1 | C1: Weak | D1: ="""" & "cas-" & B1 & """: """ & A1 & """," -> "cas-481-30-1": "Epitestesterone", | E1: ="""" & "cas-" & B1 & """: """ & C1 & """," -> "cas-481-30-1": "Weak",
A2: di-n-Butyl phthalate (DBuP) | B2: 84-74-2 | C2: Weak | D2: ="""" & "cas-" & B2 & """: """ & A2 & """," -> "cas-84-74-2": "di-n-Butyl phthalate (DBuP)", | E2: ="""" & "cas-" & B2 & """: """ & C2 & """," -> "cas-84-74-2": "Weak",
A3: 17b-Hydroxyetiocholan-3-one | B3: 571-22-2 | C3: Weak | D3: ="""" & "cas-" & B3 & """: """ & A3 & """," -> "cas-571-22-2": "17b-Hydroxyetiocholan-3-one", | E3: ="""" & "cas-" & B3 & """: """ & C3 & """," -> "cas-571-22-2": "Weak",
A4: Chrysene | B4: 218-01-9 | C4: Weak | D4: ="""" & "cas-" & B4 & """: """ & A4 & """," -> "cas-218-01-9": "Chrysene", | E4: ="""" & "cas-" & B4 & """: """ & C4 & """," -> "cas-218-01-9": "Weak",
A5: 2,4-Hydroxybenzophenone | B5: 131-56-6 | C5: Weak | D5: ="""" & "cas-" & B5 & """: """ & A5 & """," -> "cas-131-56-6": "2,4-Hydroxybenzophenone", | E5: ="""" & "cas-" & B5 & """: """ & C5 & """," -> "cas-131-56-6": "Weak",
A6: Phenol red | B6: 143-74-8 | C6: Weak | D6: ="""" & "cas-" & B6 & """: """ & A6 & """," -> "cas-143-74-8": "Phenol red", | E6: ="""" & "cas-" & B6 & """: """ & C6 & """," -> "cas-143-74-8": "Weak",
A7: Lindane (gama-HCH) | B7: 58-89-9 | C7: Weak | D7: ="""" & "cas-" & B7 & """: """ & A7 & """," -> "cas-58-89-9": "Lindane (gama-HCH)", | E7: ="""" & "cas-" & B7 & """: """ & C7 & """," -> "cas-58-89-9": "Weak",
A8: Dieldrin | B8: 60-57-1 | C8: Weak | D8: ="""" & "cas-" & B8 & """: """ & A8 & """," -> "cas-60-57-1": "Dieldrin", | E8: ="""" & "cas-" & B8 & """: """ & C8 & """," -> "cas-60-57-1": "Weak",
A9: Dexamethasone | B9: 50-02-2 | C9: Weak | D9: ="""" & "cas-" & B9 & """: """ & A9 & """," -> "cas-50-02-2": "Dexamethasone", | E9: ="""" & "cas-" & B9 & """: """ & C9 & """," -> "cas-50-02-2": "Weak",
A10: Phenolphthalin | B10: 81-90-3 | C10: Weak | D10: ="""" & "cas-" & B10 & """: """ & A10 & """," -> "cas-81-90-3": "Phenolphthalin", | E10: ="""" & "cas-" & B10 & """: """ & C10 & """," -> "cas-81-90-3": "Weak",
A11: 4,4'-Sulfonyldiphenol | B11: 80-09-1 | C11: Weak | D11: ="""" & "cas-" & B11 & """: """ & A11 & """," -> "cas-80-09-1": "4,4'-Sulfonyldiphenol", | E11: ="""" & "cas-" & B11 & """: """ & C11 & """," -> "cas-80-09-1": "Weak",
A12: 4,4'-Dichlorobiphenyl | B12: 2050-68-2 | C12: Weak | D12: ="""" & "cas-" & B12 & """: """ & A12 & """," -> "cas-2050-68-2": "4,4'-Dichlorobiphenyl", | E12: ="""" & "cas-" & B12 & """: """ & C12 & """," -> "cas-2050-68-2": "Weak",
... A74: 16b-OH-16-Methyl-3-methyl-estradiol | B74: 5108-94-1 | C74: Moderate | D74: ="""" & "cas-" & B74 & """: """ & A74 & """," -> "cas-5108-94-1": "16b-OH-16-Methyl-3-methyl-estradiol", | E74: ="""" & "cas-" & B74 & """: """ & C74 & """," -> "cas-5108-94-1": "Moderate",
